<?xml version="1.0"?>
<robot name="hand">
  <joint name="base_link" type="fixed">
    <origin xyz="0. 0. 0." rpy="0. 0. 0."/>
    <parent link="ability_hand"/>
    <child link="connector_plate"/>
  </joint>
  <joint name="connector_plate_joint" type="fixed">
    <origin xyz="0. 0.035 0.02 " rpy="-1.5707964 0. 0. "/>
    <parent link="connector_plate"/>
    <child link="wrist_connector"/>
  </joint>
  <joint name="index_q1" type="revolute">
    <origin xyz="0.0289775 0.0409529 -0.0256247" rpy="2.8641052 0.0198338 -0.1568503"/>
    <parent link="wrist_connector"/>
    <child link="index_L1"/>
    <axis xyz="1. 0. 0."/>
    <limit lower="0.1000074" upper="1.8675023" effort="5." velocity="8.0677775"/>
  </joint>
  <joint name="index_q2" type="revolute">
    <origin xyz="0. 0.0032577 -0.0384727" rpy="0.8080874 0. 0. "/>
    <parent link="index_L1"/>
    <child link="index_L2"/>
    <axis xyz="1. 0. 0."/>
    <limit lower="0." upper="2.2165682" effort="0." velocity="8.0677775"/>
		<mimic joint = "index_q1" multiplier =  "1.05851325" offset = "0"/>
  </joint>
  <joint name="middle_q1" type="revolute">
    <origin xyz="0.0095579 0.0439545 -0.022537 " rpy="2.8685586 -0.0177729 -0.0780471"/>
    <parent link="wrist_connector"/>
    <child link="middle_L1"/>
    <axis xyz="1. 0. 0."/>
    <limit lower="0.1399754" upper="1.868375" effort="5." velocity="8.0677775"/>
  </joint>
  <joint name="middle_q2" type="revolute">
    <origin xyz="0. 0.0032577 -0.0384727" rpy="0.8080874 0. 0. "/>
    <parent link="middle_L1"/>
    <child link="middle_L2"/>
    <axis xyz="1. 0. 0."/>
    <limit lower="0." upper="2.2165682" effort="5." velocity="8.0677775"/>
		<mimic joint = "middle_q1" multiplier =  "1.05851325" offset = "0"/>
  </joint>
  <joint name="palm_fixed" type="fixed">
    <origin xyz="0.024752 0.0264443 -0.0888265" rpy="3.1162112 -0.0908633 -0.0312166"/>
    <parent link="wrist_connector"/>
    <child link="palm"/>
  </joint>
  <joint name="pinky_q1" type="revolute">
    <origin xyz="-0.029837 0.0407557 -0.0308493" rpy="2.863189 -0.0403512 0.0684035"/>
    <parent link="wrist_connector"/>
    <child link="pinky_L1"/>
    <axis xyz="1. 0. 0."/>
    <limit lower="0.1302016" upper="1.6587609" effort="5." velocity="8.0677775"/>
  </joint>
  <joint name="pinky_q2" type="revolute">
    <origin xyz="0. 0.0032577 -0.0384727" rpy="0.8080874 0. 0. "/>
    <parent link="pinky_L1"/>
    <child link="pinky_L2"/>
    <axis xyz="1. 0. 0."/>
    <limit lower="0." upper="2.2165682" effort="5." velocity="8.0677775"/>
		<mimic joint = "pinky_q1" multiplier =  "1.05851325" offset = "0"/>
  </joint>
  <joint name="ring_q1" type="revolute">
    <origin xyz="-0.0106353 0.0434727 -0.0249167" rpy="2.8661923 -0.0540403 0.0041775"/>
    <parent link="wrist_connector"/>
    <child link="ring_L1"/>
    <axis xyz="1. 0. 0."/>
    <limit lower="0.0951204" upper="1.8675023" effort="5." velocity="8.0677775"/>
  </joint>
  <joint name="ring_q2" type="revolute">
    <origin xyz="0. 0.0032577 -0.0384727" rpy="0.8080874 0. 0. "/>
    <parent link="ring_L1"/>
    <child link="ring_L2"/>
    <axis xyz="1. 0. 0."/>
    <limit lower="0." upper="2.2165682" effort="5." velocity="8.0677775"/>
		<mimic joint = "ring_q1" multiplier =  "1.05851325" offset = "0"/>
  </joint>
  <joint name="thumb_q1" type="revolute">
    <origin xyz="0.024752 0.0264443 -0.0888264" rpy="-0.4604883 1.4764616 -0.3040145"/>
    <parent link="wrist_connector"/>
    <child link="thumb_L1"/>
    <axis xyz="1. 0. 0."/>
    <limit lower="0.1596976" upper="1.9198622" effort="5." velocity="17453.2925199"/>
  </joint>
  <joint name="thumb_q2" type="revolute">
    <origin xyz="-0.0147507 0. 0.0278284" rpy="-3.1415927 0. -1.3089969"/>
    <parent link="thumb_L1"/>
    <child link="thumb_L2"/>
    <axis xyz="1. 0. 0."/>
    <limit lower="0.0506145" upper="1.569051" effort="5." velocity="8.0677775"/>
  </joint>
  <link name="ability_hand"/>
  <link name="index_L1">
    <inertial>
      <origin xyz="0. 0. 0." rpy="0. 0. 0."/>
      <mass value="0.0063589"/>
      <inertia ixx="0." ixy="0." ixz="0." iyy="0." iyz="0." izz="0."/>
    </inertial>


    <visual>
      <origin xyz="0. 0.0032577 -0.0384727" rpy="1.5707964 1.4863216 1.5707964"/>
      <geometry>
        <mesh filename="urdf_meshes/index_L1_visuals_index_mesh_1.obj" scale="1. 1. 1."/>
      </geometry>
    </visual>

    <collision>
      <origin xyz="0. 0.0032577 -0.0384727" rpy="1.5707964 1.4863216 1.5707964"/>
      <geometry>
        <mesh filename="urdf_meshes/index_L1_collisions_mesh_0.obj" scale="1. 1. 1."/>
      </geometry>
    </collision>
  </link>
  <link name="connector_plate">
    <inertial>
      <origin xyz="0. 0. 0." rpy="0. 0. 0."/>
      <mass value="0.05"/>
      <inertia ixx="0." ixy="0." ixz="0." iyy="0." iyz="0." izz="0."/>
    </inertial>
  </link>
  <link name="index_L2">
    <inertial>
      <origin xyz="0. 0. 0." rpy="0. 0. 0."/>
      <mass value="0.00645"/>
      <inertia ixx="0." ixy="0." ixz="0." iyy="0." iyz="0." izz="0."/>
    </inertial>
    <visual>
      <origin xyz="0. 0. -0.0091241" rpy="0. 1.5707963 0. "/>
      <geometry>
        <mesh filename="urdf_meshes/index_L2_visuals_index_mesh_2.obj" scale="1. 1. 1."/>
      </geometry>
    </visual>

    <collision>
      <origin xyz="0. 0. -0.0091241" rpy="0. 1.5707963 0. "/>
      <geometry>
        <mesh filename="urdf_meshes/index_L2_collisions_mesh_0.obj" scale="1. 1. 1."/>
      </geometry>
    </collision>
  </link>
  <link name="middle_L1">
    <inertial>
      <origin xyz="0. 0. 0." rpy="0. 0. 0."/>
      <mass value="0.0063589"/>
      <inertia ixx="0." ixy="0." ixz="0." iyy="0." iyz="0." izz="0."/>
    </inertial>

    <visual>
      <origin xyz="0. 0.0032577 -0.0384727" rpy="1.5707964 1.4863216 1.5707964"/>
      <geometry>
        <mesh filename="urdf_meshes/index_L1_visuals_index_mesh_1.obj" scale="1. 1. 1."/>
      </geometry>
    </visual>
    
    <collision>
      <origin xyz="0. 0.0032577 -0.0384727" rpy="1.5707964 1.4863216 1.5707964"/>
      <geometry>
        <mesh filename="urdf_meshes/index_L1_collisions_mesh_0.obj" scale="1. 1. 1."/>
      </geometry>
    </collision>
  </link>
  <link name="middle_L2">
    <inertial>
      <origin xyz="0. 0. 0." rpy="0. 0. 0."/>
      <mass value="0.00645"/>
      <inertia ixx="0." ixy="0." ixz="0." iyy="0." iyz="0." izz="0."/>
    </inertial>

    <visual>
      <origin xyz="0. 0. -0.0091241" rpy="0. 1.5707963 0. "/>
      <geometry>
        <mesh filename="urdf_meshes/index_L2_visuals_index_mesh_2.obj" scale="1. 1. 1."/>
      </geometry>
    </visual>

    <collision>
      <origin xyz="0. 0. -0.0091241" rpy="0. 1.5707963 0. "/>
      <geometry>
        <mesh filename="urdf_meshes/index_L2_collisions_mesh_0.obj" scale="1. 1. 1."/>
      </geometry>
    </collision>
  </link>

  <link name="palm">
    <inertial>
      <origin xyz="0. 0. 0." rpy="0. 0. 0."/>
      <mass value="0.000001"/>
      <inertia ixx="0." ixy="0." ixz="0." iyy="0." iyz="0." izz="0."/>
    </inertial>

    <visual>
      <origin xyz="0. -0. 0." rpy="-0. 0.0578587 -0. "/>
      <geometry>
        <mesh filename="urdf_meshes/palm_collisions_mesh_0.obj" scale="1. 1. 1."/>
      </geometry>
    </visual>

    <collision>
      <origin xyz="0. -0. 0." rpy="-0. 0.0578587 -0. "/>
      <geometry>
        <mesh filename="urdf_meshes/palm_collisions_mesh_0.obj" scale="1. 1. 1."/>
      </geometry>
    </collision>
  </link>

  <link name="pinky_L1">
    <inertial>
      <origin xyz="0. 0. 0." rpy="0. 0. 0."/>
      <mass value="0.0063589"/>
      <inertia ixx="0." ixy="0." ixz="0." iyy="0." iyz="0." izz="0."/>
    </inertial>

    <visual>
      <origin xyz="0. 0.0032577 -0.0384727" rpy="1.5707964 1.4863216 1.5707964"/>
      <geometry>
        <mesh filename="urdf_meshes/index_L1_visuals_index_mesh_1.obj" scale="1. 1. 1."/>
      </geometry>
    </visual>

    <collision>
      <origin xyz="0. 0.0032577 -0.0384727" rpy="1.5707964 1.4863216 1.5707964"/>
      <geometry>
        <mesh filename="urdf_meshes/index_L1_collisions_mesh_0.obj" scale="1. 1. 1."/>
      </geometry>
    </collision>
  </link>
  <link name="pinky_L2">
    <inertial>
      <origin xyz="0. 0. 0." rpy="0. 0. 0."/>
      <mass value="0.00645"/>
      <inertia ixx="0." ixy="0." ixz="0." iyy="0." iyz="0." izz="0."/>
    </inertial>

    <visual>
      <origin xyz="0. 0. -0.0091241" rpy="0. 1.5707963 0. "/>
      <geometry>
        <mesh filename="urdf_meshes/index_L2_visuals_index_mesh_2.obj" scale="1. 1. 1."/>
      </geometry>
    </visual>

    <collision>
      <origin xyz="0. 0. -0.0091241" rpy="0. 1.5707963 0. "/>
      <geometry>
        <mesh filename="urdf_meshes/index_L2_collisions_mesh_0.obj" scale="1. 1. 1."/>
      </geometry>
    </collision>
  </link>
  <link name="ring_L1">
    <inertial>
      <origin xyz="0. 0. 0." rpy="0. 0. 0."/>
      <mass value="0.0063589"/>
      <inertia ixx="0." ixy="0." ixz="0." iyy="0." iyz="0." izz="0."/>
    </inertial>

    <visual>
      <origin xyz="0. 0.0032577 -0.0384727" rpy="1.5707964 1.4863216 1.5707964"/>
      <geometry>
        <mesh filename="urdf_meshes/index_L1_visuals_index_mesh_1.obj" scale="1. 1. 1."/>
      </geometry>
    </visual>

    <collision>
      <origin xyz="0. 0.0032577 -0.0384727" rpy="1.5707964 1.4863216 1.5707964"/>
      <geometry>
        <mesh filename="urdf_meshes/index_L1_collisions_mesh_0.obj" scale="1. 1. 1."/>
      </geometry>
    </collision>
  </link>
  <link name="ring_L2">
    <inertial>
      <origin xyz="0. 0. 0." rpy="0. 0. 0."/>
      <mass value="0.00645"/>
      <inertia ixx="0." ixy="0." ixz="0." iyy="0." iyz="0." izz="0."/>
    </inertial>

    <visual>
      <origin xyz="0. 0. -0.0091241" rpy="0. 1.5707963 0. "/>
      <geometry>
        <mesh filename="urdf_meshes/index_L2_visuals_index_mesh_2.obj" scale="1. 1. 1."/>
      </geometry>
    </visual>

    <collision>
      <origin xyz="0. 0. -0.0091241" rpy="0. 1.5707963 0. "/>
      <geometry>
        <mesh filename="urdf_meshes/index_L2_collisions_mesh_0.obj" scale="1. 1. 1."/>
      </geometry>
    </collision>
  </link>
  <link name="thumb_L1">
    <inertial>
      <origin xyz="0. 0. 0." rpy="0. 0. 0."/>
      <mass value="0.0026834"/>
      <inertia ixx="0." ixy="0." ixz="0." iyy="0." iyz="0." izz="0."/>
    </inertial>

    <visual>
      <origin xyz="-0.0147507 0. 0.0278284" rpy="1.8325957 -1.5707964 0. "/>
      <geometry>
        <mesh filename="urdf_meshes/thumb_mesh_1.obj" scale="1. 1. 1."/>
      </geometry>
    </visual>


    <collision>
      
      <origin xyz="-0.0147507 0. 0.0278284" rpy="1.8325957 -1.5707964 0. "/>
      <geometry>
        <mesh filename="urdf_meshes/thumb_L1_collision.obj" scale="1. 1. 1."/>
      </geometry>

    </collision>
  </link>

  
  <link name="thumb_L2">
    <inertial>
      <origin xyz="0. 0. 0." rpy="0. 0. 0."/>
      <mass value="0.0055"/>
      <inertia ixx="0." ixy="0." ixz="0." iyy="0." iyz="0." izz="0."/>
    </inertial>

    <visual>
      <origin xyz="0.0039348 0.0233402 -0.0651867" rpy="-1.5707957 1.2269664 1.5707964"/>
      <geometry>
        <mesh filename="urdf_meshes/thumb_mesh_2.obj" scale="1. 1. 1."/>
      </geometry>
    </visual>
    
    <collision>
      <origin xyz="0.0039348 0.0233402 -0.0651867" rpy="-1.5707957 1.2269664 1.5707964"/>
      <geometry>
        <mesh filename="urdf_meshes/thumb_L2_collisions_mesh_0.obj" scale="1. 1. 1."/>
      </geometry>
    </collision>
  </link>

  <link name = "index_tip">
  </link>
  <joint name="index_tip_joint" type="fixed">
    <origin xyz="0. -0.015 -0.035" rpy="0. 0. 0."/>
    <parent link="index_L2"/>
    <child link="index_tip"/>
  </joint>
  <link name="middle_tip">
  </link>
  <joint name="middle_tip_joint" type="fixed">
    <origin xyz="0. -0.015 -0.035" rpy="0. 0. 0."/>
    <parent link="middle_L2"/>
    <child link="middle_tip"/>
  </joint>
  <link name="pinky_tip">   
  </link>
  <joint name="pinky_tip_joint" type="fixed">
    <origin xyz="0. -0.015 -0.035" rpy="0. 0. 0."/>
    <parent link="pinky_L2"/>   
    <child link="pinky_tip"/>
  </joint>
  <link name="ring_tip">
  </link>
  <joint name="ring_tip_joint" type="fixed">
    <origin xyz="0. -0.015 -0.035" rpy="0. 0. 0."/>
    <parent link="ring_L2"/>
    <child link="ring_tip"/>
  </joint>
  <link name="thumb_tip">
  </link>
  <joint name="thumb_tip_joint" type="fixed">
    <origin xyz="0.0 0.028 -0.057" rpy="0. 0. 0."/>
    <parent link="thumb_L2"/>
    <child link="thumb_tip"/>
  </joint>
  
  <link name="wrist_connector">
    <inertial>
      <origin xyz="0. 0. 0." rpy="0. 0. 0."/>
      <mass value="0.4"/>
      <inertia ixx="0." ixy="0." ixz="0." iyy="0." iyz="0." izz="0."/>
    </inertial>
  </link>
</robot>
