<?xml version="1.0"?>
<robot name="ROBOTIQ_2F_CFG140_simple">
    <joint name="finger_joint" type="revolute">
        <origin xyz="0. -0.030601 0.054905" rpy="0.8457962 0.0000001 -3.1415925"/>
        <parent link="robotiq_arg2f_base_link"/>
        <child link="left_outer_knuckle"/>
        <axis xyz="1. 0. 0."/>
        <limit lower="0." upper="0.7" effort="60000." velocity="2."/>
    </joint>
    <joint name="left_inner_finger_joint" type="revolute">
        <origin xyz="0. 0.0817554 -0.0282203" rpy="-0.725 0. 0. "/>
        <parent link="left_outer_finger"/>
        <child link="left_inner_finger"/>
        <axis xyz="1. 0. 0."/>
        <limit lower="-0.8757" upper="0.8757" effort="60000." velocity="2."/>
    </joint>
    <joint name="left_inner_finger_pad_joint" type="fixed">
        <origin xyz="0. 0.0457554 -0.0272203" rpy="0. -1.5707963 0. "/>
        <parent link="left_inner_finger"/>
        <child link="left_inner_finger_pad"/>
    </joint>
    <joint name="left_inner_knuckle_joint" type="continuous">
        <origin xyz="0. 0.0085067 -0.0170686" rpy="0.7249998 0. 0. "/>
        <parent link="left_inner_finger"/>
        <child link="left_inner_knuckle"/>
        <limit lower="-1.8757" upper="1.8757" effort="60000." velocity="2."/>
        <axis xyz="1. 0. 0."/>
    </joint>
    <joint name="left_outer_finger_joint" type="fixed">
        <origin xyz="0. 0.01822 -0.0260018" rpy="3.1415927 0.0000001 -3.1415927"/>
        <parent link="left_outer_knuckle"/>
        <child link="left_outer_finger"/>
    </joint>
    <joint name="right_inner_finger_joint" type="revolute">
        <origin xyz="0. 0.0817554 -0.0282203" rpy="-0.725 0. 0. "/>
        <parent link="right_outer_finger"/>
        <child link="right_inner_finger"/>
        <axis xyz="1. 0. 0."/>
        <limit lower="-0.8757" upper="0.8757" effort="60000." velocity="2."/>
    </joint>
    <joint name="right_inner_finger_pad_joint" type="fixed">
        <origin xyz="0. 0.0457554 -0.0272203" rpy="0. -1.5707964 0. "/>
        <parent link="right_inner_finger"/>
        <child link="right_inner_finger_pad"/>
    </joint>
    <joint name="right_inner_knuckle_joint" type="continuous">
        <origin xyz="-0. 0.0035254 -0.0175857" rpy="0.725 -0.0000002 0. "/>
        <parent link="right_inner_finger"/>
        <child link="right_inner_knuckle"/>
        <axis xyz="1. 0. 0."/>
        <limit lower="-1.8757" upper="1.8757" effort="60000." velocity="2."/>
    </joint>
    <joint name="right_outer_finger_joint" type="fixed">
        <origin xyz="0. 0.01822 0.0260018" rpy="0. 0. 0."/>
        <parent link="right_outer_knuckle"/>
        <child link="right_outer_finger"/>
    </joint>
    <joint name="right_outer_knuckle_joint" type="revolute">
        <origin xyz="0. 0.030601 0.054905" rpy="2.2957964 0. -3.1415925"/>
        <parent link="robotiq_arg2f_base_link"/>
        <child link="right_outer_knuckle"/>
        <axis xyz="1. 0. 0."/>
        <limit lower="-0.725" upper="0.725" effort="10000000." velocity="2."/>
    </joint>
    <joint name="root_joint" type="fixed">
        <origin xyz="0. 0. -0.125" rpy="0. 0. 0."/>
        <parent link="Root"/>
        <child link="robotiq_arg2f_base_link"/>
    </joint>
    <link name="Root"/>
    <link name="left_inner_finger">
        <inertial>
            <origin xyz="0.0003 0.0160078 -0.0136946" rpy="0. 0. 0."/>
            <mass value="0.0104003"/>
            <inertia ixx="0.0000027" ixy="0." ixz="0." iyy="0.0000008" iyz="0." izz="0.0000023"/>
        </inertial>
        <visual>
            <origin xyz="0. 0. 0." rpy="-0. 0. 0."/>
            <geometry>
                <mesh filename="meshes/right_inner_finger_visuals_mesh_0.obj" scale="1. 1. 1."/>
            </geometry>
        </visual>
        <collision>
            <origin xyz="0. 0. 0." rpy="-0. 0. 0."/>
            <geometry>
                <mesh filename="meshes/right_inner_finger_collisions_mesh_0.obj" scale="1. 1. 1."/>
            </geometry>
        </collision>
    </link>
    <link name="left_inner_finger_pad">
        <visual>
            <origin xyz="0. -0. 0." rpy="0. 0.0 0. "/>
            <geometry>
                <mesh filename="meshes/fingerpad.obj" scale="1. 1. 1."/>
                <!-- <box size="0.027 0.065 0.0075"/> -->
            </geometry>
        </visual>
        <collision>
            <origin xyz="0. -0. 0." rpy="0. 0.0 0. "/>
            <geometry>
                <mesh filename="meshes/fingerpad.obj" scale="1. 1. 1."/>
            </geometry>
        </collision>
    </link>
    <link name="left_inner_knuckle">
        <inertial>
            <origin xyz="0.000123 0.0507851 0.0010397" rpy="0. 0. 0."/>
            <mass value="0.0271177"/>
            <inertia ixx="0.0000262" ixy="0." ixz="0." iyy="0.0000028" iyz="0." izz="0.0000284"/>
        </inertial>
        <visual>
            <origin xyz="0. -0.1020182 0.0029162" rpy="0.0000001 0. 0. "/>
            <geometry>
                <mesh filename="meshes/right_inner_knuckle_visuals_mesh_0.obj" scale="1. 1. 1."/>
            </geometry>
        </visual>
        <collision>
            <origin xyz="0. -0.1020182 0.0029162" rpy="0.0000001 0. 0. "/>
            <geometry>
                <mesh filename="meshes/right_inner_knuckle_collisions_mesh_0.obj" scale="1. 1. 1."/>
            </geometry>
        </collision>
    </link>
    <link name="left_outer_finger">
        <inertial>
            <origin xyz="0.0003012 0.0373908 -0.0208027" rpy="0. 0. 0."/>
            <mass value="0.0226142"/>
            <inertia ixx="0.0000153" ixy="0." ixz="0." iyy="0.0000062" iyz="0." izz="0.0000116"/>
        </inertial>
        <visual>
            <origin xyz="0. 0. 0." rpy="0. 0. 0."/>
            <geometry>
                <mesh filename="meshes/right_outer_finger_visuals_mesh_0.obj" scale="1. 1. 1."/>
            </geometry>
        </visual>
        <collision>
            <origin xyz="0. 0. 0." rpy="0. 0. 0."/>
            <geometry>
                <mesh filename="meshes/right_outer_finger_collisions_mesh_0.obj" scale="1. 1. 1."/>
            </geometry>
        </collision>
    </link>
    <link name="left_outer_knuckle">
        <inertial>
            <origin xyz="-0.0002 0.0199436 0.0292245" rpy="0. 0. 0."/>
            <mass value="0.008532"/>
            <inertia ixx="0.0000029" ixy="0." ixz="0." iyy="0.0000019" iyz="0." izz="0.0000012"/>
        </inertial>
        <visual>
            <origin xyz="0. 0. 0." rpy="3.1415927 0.0000001 -3.1415927"/>
            <geometry>
                <mesh filename="meshes/right_outer_knuckle_visuals_mesh_0.obj" scale="1. 1. 1."/>
            </geometry>
        </visual>
        <collision>
            <origin xyz="0. 0. 0." rpy="3.1415927 0.0000001 -3.1415927"/>
            <geometry>
                <mesh filename="meshes/right_outer_knuckle_collisions_mesh_0.obj" scale="1. 1. 1."/>
            </geometry>
        </collision>
    </link>
    <link name="right_inner_finger">
        <inertial>
            <origin xyz="0.0003 0.0160078 -0.0136946" rpy="0. 0. 0."/>
            <mass value="0.0104003"/>
            <inertia ixx="0.0000027" ixy="0." ixz="0." iyy="0.0000008" iyz="0." izz="0.0000023"/>
        </inertial>
        <visual>
            <origin xyz="0. 0. 0." rpy="0. 0. 0."/>
            <geometry>
                <mesh filename="meshes/right_inner_finger_visuals_mesh_0.obj" scale="1. 1. 1."/>
            </geometry>
        </visual>
        <collision>
            <origin xyz="0. 0. 0." rpy="0. 0. 0."/>
            <geometry>
                <mesh filename="meshes/right_inner_finger_collisions_mesh_0.obj" scale="1. 1. 1."/>
            </geometry>
        </collision>
    </link>
    <link name="right_inner_finger_pad">
        <visual>
            <origin xyz="0. -0. 0." rpy="0. 0.0 0. "/>
            <geometry>
                <mesh filename="meshes/fingerpad.obj" scale="1. 1. 1."/>
                <!-- <box size="0.027 0.065 0.0075"/> -->
            </geometry>
        </visual>
        <collision>
            <origin xyz="0. -0. 0." rpy="0. 0.0 0. "/>
            <geometry>
                <mesh filename="meshes/fingerpad.obj" scale="1. 1. 1."/>
            </geometry>
        </collision>
    </link>
    <link name="right_inner_knuckle">
        <inertial>
            <origin xyz="0.000123 0.0507851 0.0010397" rpy="0. 0. 0."/>
            <mass value="0.0271177"/>
            <inertia ixx="0.0000262" ixy="0." ixz="0." iyy="0.0000028" iyz="0." izz="0.0000284"/>
        </inertial>
        <visual>
            <origin xyz="0. -0.0979468 -0. " rpy="-0. 0. 0."/>
            <geometry>
                <mesh filename="meshes/right_inner_knuckle_visuals_mesh_0.obj" scale="1. 1. 1."/>
            </geometry>
        </visual>
        <collision>
            <origin xyz="0. -0.0979468 -0. " rpy="-0. 0. 0."/>
            <geometry>
                <mesh filename="meshes/right_inner_knuckle_collisions_mesh_0.obj" scale="1. 1. 1."/>
            </geometry>
        </collision>
    </link>
    <link name="right_outer_finger">
        <inertial>
            <origin xyz="0.0003012 0.0373908 -0.0208027" rpy="0. 0. 0."/>
            <mass value="0.0226142"/>
            <inertia ixx="0.0000153" ixy="0." ixz="0." iyy="0.0000062" iyz="0." izz="0.0000116"/>
        </inertial>
        <visual>
            <origin xyz="0. 0. 0." rpy="0. 0. 0."/>
            <geometry>
                <mesh filename="meshes/right_outer_finger_visuals_mesh_0.obj" scale="1. 1. 1."/>
            </geometry>
        </visual>
        <collision>
            <origin xyz="0. 0. 0." rpy="0. 0. 0."/>
            <geometry>
                <mesh filename="meshes/right_outer_finger_collisions_mesh_0.obj" scale="1. 1. 1."/>
            </geometry>
        </collision>
    </link>
    <link name="right_outer_knuckle">
        <inertial>
            <origin xyz="-0.0002 0.0199436 0.0292245" rpy="0. 0. 0."/>
            <mass value="0.008532"/>
            <inertia ixx="0.0000029" ixy="0." ixz="0." iyy="0.0000019" iyz="0." izz="0.0000012"/>
        </inertial>
        <visual>
            <origin xyz="0. 0. 0." rpy="0. 0. 0."/>
            <geometry>
                <mesh filename="meshes/right_outer_knuckle_visuals_mesh_0.obj" scale="1. 1. 1."/>
            </geometry>
        </visual>
        <collision>
            <origin xyz="0. 0. 0." rpy="0. 0. 0."/>
            <geometry>
                <mesh filename="meshes/right_outer_knuckle_collisions_mesh_0.obj" scale="1. 1. 1."/>
            </geometry>
        </collision>
    </link>
    <link name="robotiq_arg2f_base_link">
        <inertial>
            <origin xyz="0.0000001 -0.0000047 0.03145 " rpy="0. 0. 0."/>
            <mass value="0.22652"/>
            <inertia ixx="0.0002" ixy="0." ixz="0." iyy="0.0001783" iyz="0." izz="0.0001348"/>
        </inertial>
        <visual>
            <origin xyz="0. 0. 0." rpy="0. 0. 0."/>
            <geometry>
                <mesh filename="meshes/robotiq_arg2f_base_link_visuals_mesh_0.obj" scale="1. 1. 1."/>
            </geometry>
        </visual>
        <collision>
            <origin xyz="0. 0. 0." rpy="0. 0. 0."/>
            <geometry>
                <mesh filename="meshes/robotiq_arg2f_base_link_collisions_mesh_0.obj" scale="1. 1. 1."/>
            </geometry>
        </collision>
    </link>
</robot>
